2020-02-24 08:55:37 WARNING (MainThread) [homeassistant.loader] You are using a custom integration for zigbee2mqtt_networkmap which has not been tested by Home Assistant. This component might cause stability problems, be sure to disable it if you do experience issues with Home Assistant.
2020-02-24 08:55:37 WARNING (MainThread) [homeassistant.loader] You are using a custom integration for smartir which has not been tested by Home Assistant. This component might cause stability problems, be sure to disable it if you do experience issues with Home Assistant.
2020-02-24 08:55:37 WARNING (MainThread) [homeassistant.loader] You are using a custom integration for hacs which has not been tested by Home Assistant. This component might cause stability problems, be sure to disable it if you do experience issues with Home Assistant.
2020-02-24 08:55:37 ERROR (Recorder) [homeassistant.components.recorder] Error during connection setup: (MySQLdb._exceptions.OperationalError) (2002, "Can't connect to MySQL server on '192.168.13.2' (115)")
(Background on this error at: http://sqlalche.me/e/e3q8) (retrying in 3 seconds)
2020-02-24 08:55:40 ERROR (Recorder) [homeassistant.components.recorder] Error during connection setup: (MySQLdb._exceptions.OperationalError) (2002, "Can't connect to MySQL server on '192.168.13.2' (115)")
(Background on this error at: http://sqlalche.me/e/e3q8) (retrying in 3 seconds)
2020-02-24 08:55:43 ERROR (Recorder) [homeassistant.components.recorder] Error during connection setup: (MySQLdb._exceptions.OperationalError) (2002, "Can't connect to MySQL server on '192.168.13.2' (115)")
(Background on this error at: http://sqlalche.me/e/e3q8) (retrying in 3 seconds)
2020-02-24 08:55:46 ERROR (Recorder) [homeassistant.components.recorder] Error during connection setup: (MySQLdb._exceptions.OperationalError) (2002, "Can't connect to MySQL server on '192.168.13.2' (115)")
(Background on this error at: http://sqlalche.me/e/e3q8) (retrying in 3 seconds)
2020-02-24 08:55:49 ERROR (Recorder) [homeassistant.components.recorder] Error during connection setup: (MySQLdb._exceptions.OperationalError) (2002, "Can't connect to MySQL server on '192.168.13.2' (115)")
(Background on this error at: http://sqlalche.me/e/e3q8) (retrying in 3 seconds)
2020-02-24 08:55:52 ERROR (Recorder) [homeassistant.components.recorder] Error during connection setup: (MySQLdb._exceptions.OperationalError) (2002, "Can't connect to MySQL server on '192.168.13.2' (115)")
(Background on this error at: http://sqlalche.me/e/e3q8) (retrying in 3 seconds)
2020-02-24 08:55:55 ERROR (Recorder) [homeassistant.components.recorder] Error during connection setup: (MySQLdb._exceptions.OperationalError) (2002, "Can't connect to MySQL server on '192.168.13.2' (115)")
(Background on this error at: http://sqlalche.me/e/e3q8) (retrying in 3 seconds)
2020-02-24 08:55:58 ERROR (Recorder) [homeassistant.components.recorder] Error during connection setup: (MySQLdb._exceptions.OperationalError) (2002, "Can't connect to MySQL server on '192.168.13.2' (115)")
(Background on this error at: http://sqlalche.me/e/e3q8) (retrying in 3 seconds)
2020-02-24 08:56:01 ERROR (Recorder) [homeassistant.components.recorder] Error during connection setup: (MySQLdb._exceptions.OperationalError) (2002, "Can't connect to MySQL server on '192.168.13.2' (115)")
(Background on this error at: http://sqlalche.me/e/e3q8) (retrying in 3 seconds)
2020-02-24 08:56:04 ERROR (Recorder) [homeassistant.components.recorder] Error during connection setup: (MySQLdb._exceptions.OperationalError) (2002, "Can't connect to MySQL server on '192.168.13.2' (115)")
(Background on this error at: http://sqlalche.me/e/e3q8) (retrying in 3 seconds)
2020-02-24 08:56:04 ERROR (MainThread) [homeassistant.setup] Setup failed for recorder: Integration failed to initialize.
2020-02-24 08:56:06 ERROR (MainThread) [homeassistant.setup] Unable to set up dependencies of history. Setup failed for dependencies: recorder
2020-02-24 08:56:06 ERROR (MainThread) [homeassistant.setup] Setup failed for history: Could not set up all dependencies.
2020-02-24 08:56:11 ERROR (MainThread) [homeassistant.setup] Unable to set up dependencies of logbook. Setup failed for dependencies: recorder
2020-02-24 08:56:11 ERROR (MainThread) [homeassistant.setup] Setup failed for logbook: Could not set up all dependencies.
2020-02-24 08:56:11 ERROR (MainThread) [homeassistant.setup] Unable to set up dependencies of default_config. Setup failed for dependencies: history, logbook
2020-02-24 08:56:11 ERROR (MainThread) [homeassistant.setup] Setup failed for default_config: Could not set up all dependencies.
2020-02-24 08:56:12 ERROR (MainThread) [homeassistant.components.sensor] The glances platform for the sensor integration does not support platform setup. Please remove it from your config.
2020-02-24 08:56:56 ERROR (MainThread) [homeassistant.helpers.entity] Update for sensor.internet_in_mbps fails
Traceback (most recent call last):
  File "/usr/src/homeassistant/homeassistant/helpers/entity.py", line 279, in async_update_ha_state
    await self.async_device_update()
  File "/usr/src/homeassistant/homeassistant/helpers/entity.py", line 459, in async_device_update
    await self.async_update()
  File "/usr/src/homeassistant/homeassistant/components/template/sensor.py", line 224, in async_update
    self._state = self._template.async_render()
  File "/usr/src/homeassistant/homeassistant/helpers/template.py", line 221, in async_render
    return compiled.render(kwargs).strip()
  File "/usr/local/lib/python3.7/site-packages/jinja2/environment.py", line 1090, in render
    self.environment.handle_exception()
  File "/usr/local/lib/python3.7/site-packages/jinja2/environment.py", line 832, in handle_exception
    reraise(*rewrite_traceback_stack(source=source))
  File "/usr/local/lib/python3.7/site-packages/jinja2/_compat.py", line 28, in reraise
    raise value.with_traceback(tb)
  File "<template>", line 1, in top-level template code
TypeError: unsupported operand type(s) for -: 'NoneType' and 'int'
2020-02-24 08:56:56 ERROR (MainThread) [homeassistant.helpers.entity] Update for sensor.internet_out_mbps fails
Traceback (most recent call last):
  File "/usr/src/homeassistant/homeassistant/helpers/entity.py", line 279, in async_update_ha_state
    await self.async_device_update()
  File "/usr/src/homeassistant/homeassistant/helpers/entity.py", line 459, in async_device_update
    await self.async_update()
  File "/usr/src/homeassistant/homeassistant/components/template/sensor.py", line 224, in async_update
    self._state = self._template.async_render()
  File "/usr/src/homeassistant/homeassistant/helpers/template.py", line 221, in async_render
    return compiled.render(kwargs).strip()
  File "/usr/local/lib/python3.7/site-packages/jinja2/environment.py", line 1090, in render
    self.environment.handle_exception()
  File "/usr/local/lib/python3.7/site-packages/jinja2/environment.py", line 832, in handle_exception
    reraise(*rewrite_traceback_stack(source=source))
  File "/usr/local/lib/python3.7/site-packages/jinja2/_compat.py", line 28, in reraise
    raise value.with_traceback(tb)
  File "<template>", line 1, in top-level template code
TypeError: unsupported operand type(s) for -: 'NoneType' and 'int'
2020-02-24 11:00:47 ERROR (MainThread) [pytautulli] Can not load data from Tautulli: http://192.168.13.1:8181/api/v2?apikey=ae776b94fe9546989cf62d6fa5f732ab&cmd=get_activity - 
2020-02-24 11:53:24 ERROR (MainThread) [pytautulli] Can not load data from Tautulli: http://192.168.13.1:8181/api/v2?apikey=ae776b94fe9546989cf62d6fa5f732ab&cmd=get_activity - 
2020-02-24 12:07:21 ERROR (MainThread) [pytautulli] Can not load data from Tautulli: http://192.168.13.1:8181/api/v2?apikey=ae776b94fe9546989cf62d6fa5f732ab&cmd=get_activity - 
2020-02-24 12:59:53 ERROR (MainThread) [homeassistant.helpers.entity] Update for calendar.holidays_holiday fails
Traceback (most recent call last):
  File "/usr/local/lib/python3.7/site-packages/urllib3/connection.py", line 157, in _new_conn
    (self._dns_host, self.port), self.timeout, **extra_kw
  File "/usr/local/lib/python3.7/site-packages/urllib3/util/connection.py", line 84, in create_connection
    raise err
  File "/usr/local/lib/python3.7/site-packages/urllib3/util/connection.py", line 74, in create_connection
    sock.connect(sa)
ConnectionRefusedError: [Errno 111] Connection refused

During handling of the above exception, another exception occurred:

Traceback (most recent call last):
  File "/usr/local/lib/python3.7/site-packages/urllib3/connectionpool.py", line 672, in urlopen
    chunked=chunked,
  File "/usr/local/lib/python3.7/site-packages/urllib3/connectionpool.py", line 376, in _make_request
    self._validate_conn(conn)
  File "/usr/local/lib/python3.7/site-packages/urllib3/connectionpool.py", line 994, in _validate_conn
    conn.connect()
  File "/usr/local/lib/python3.7/site-packages/urllib3/connection.py", line 300, in connect
    conn = self._new_conn()
  File "/usr/local/lib/python3.7/site-packages/urllib3/connection.py", line 169, in _new_conn
    self, "Failed to establish a new connection: %s" % e
urllib3.exceptions.NewConnectionError: <urllib3.connection.VerifiedHTTPSConnection object at 0x7f5c8a57bd90>: Failed to establish a new connection: [Errno 111] Connection refused

During handling of the above exception, another exception occurred:

Traceback (most recent call last):
  File "/usr/local/lib/python3.7/site-packages/requests/adapters.py", line 449, in send
    timeout=timeout
  File "/usr/local/lib/python3.7/site-packages/urllib3/connectionpool.py", line 720, in urlopen
    method, url, error=e, _pool=self, _stacktrace=sys.exc_info()[2]
  File "/usr/local/lib/python3.7/site-packages/urllib3/util/retry.py", line 436, in increment
    raise MaxRetryError(_pool, url, error or ResponseError(cause))
urllib3.exceptions.MaxRetryError: HTTPSConnectionPool(host='cloud.yeradonkey.com', port=443): Max retries exceeded with url: /remote.php/dav/calendars/Squiggley/holidays/ (Caused by NewConnectionError('<urllib3.connection.VerifiedHTTPSConnection object at 0x7f5c8a57bd90>: Failed to establish a new connection: [Errno 111] Connection refused'))

During handling of the above exception, another exception occurred:

Traceback (most recent call last):
  File "/usr/src/homeassistant/homeassistant/helpers/entity.py", line 279, in async_update_ha_state
    await self.async_device_update()
  File "/usr/src/homeassistant/homeassistant/helpers/entity.py", line 461, in async_device_update
    await self.hass.async_add_executor_job(self.update)
  File "/usr/local/lib/python3.7/concurrent/futures/thread.py", line 57, in run
    result = self.fn(*self.args, **self.kwargs)
  File "/usr/src/homeassistant/homeassistant/components/caldav/calendar.py", line 145, in update
    self.data.update()
  File "/usr/src/homeassistant/homeassistant/util/__init__.py", line 240, in wrapper
    result = method(*args, **kwargs)
  File "/usr/src/homeassistant/homeassistant/components/caldav/calendar.py", line 199, in update
    dt.start_of_local_day(), dt.start_of_local_day() + timedelta(days=1)
  File "/usr/local/lib/python3.7/site-packages/caldav/objects.py", line 594, in date_search
    response = self._query(root, 1, 'report')
  File "/usr/local/lib/python3.7/site-packages/caldav/objects.py", line 161, in _query
    url, body, depth)
  File "/usr/local/lib/python3.7/site-packages/caldav/davclient.py", line 163, in report
    "application/xml; charset=\"utf-8\""})
  File "/usr/local/lib/python3.7/site-packages/caldav/davclient.py", line 237, in request
    auth=auth, verify=self.ssl_verify_cert)
  File "/usr/local/lib/python3.7/site-packages/requests/api.py", line 60, in request
    return session.request(method=method, url=url, **kwargs)
  File "/usr/local/lib/python3.7/site-packages/requests/sessions.py", line 533, in request
    resp = self.send(prep, **send_kwargs)
  File "/usr/local/lib/python3.7/site-packages/requests/sessions.py", line 646, in send
    r = adapter.send(request, **kwargs)
  File "/usr/local/lib/python3.7/site-packages/requests/adapters.py", line 516, in send
    raise ConnectionError(e, request=request)
requests.exceptions.ConnectionError: HTTPSConnectionPool(host='cloud.yeradonkey.com', port=443): Max retries exceeded with url: /remote.php/dav/calendars/Squiggley/holidays/ (Caused by NewConnectionError('<urllib3.connection.VerifiedHTTPSConnection object at 0x7f5c8a57bd90>: Failed to establish a new connection: [Errno 111] Connection refused'))
2020-02-24 13:00:54 ERROR (MainThread) [homeassistant.helpers.entity] Update for calendar.holidays_holiday fails
Traceback (most recent call last):
  File "/usr/local/lib/python3.7/site-packages/urllib3/connection.py", line 157, in _new_conn
    (self._dns_host, self.port), self.timeout, **extra_kw
  File "/usr/local/lib/python3.7/site-packages/urllib3/util/connection.py", line 84, in create_connection
    raise err
  File "/usr/local/lib/python3.7/site-packages/urllib3/util/connection.py", line 74, in create_connection
    sock.connect(sa)
ConnectionRefusedError: [Errno 111] Connection refused

During handling of the above exception, another exception occurred:

Traceback (most recent call last):
  File "/usr/local/lib/python3.7/site-packages/urllib3/connectionpool.py", line 672, in urlopen
    chunked=chunked,
  File "/usr/local/lib/python3.7/site-packages/urllib3/connectionpool.py", line 376, in _make_request
    self._validate_conn(conn)
  File "/usr/local/lib/python3.7/site-packages/urllib3/connectionpool.py", line 994, in _validate_conn
    conn.connect()
  File "/usr/local/lib/python3.7/site-packages/urllib3/connection.py", line 300, in connect
    conn = self._new_conn()
  File "/usr/local/lib/python3.7/site-packages/urllib3/connection.py", line 169, in _new_conn
    self, "Failed to establish a new connection: %s" % e
urllib3.exceptions.NewConnectionError: <urllib3.connection.VerifiedHTTPSConnection object at 0x7f5c89634c90>: Failed to establish a new connection: [Errno 111] Connection refused

During handling of the above exception, another exception occurred:

Traceback (most recent call last):
  File "/usr/local/lib/python3.7/site-packages/requests/adapters.py", line 449, in send
    timeout=timeout
  File "/usr/local/lib/python3.7/site-packages/urllib3/connectionpool.py", line 720, in urlopen
    method, url, error=e, _pool=self, _stacktrace=sys.exc_info()[2]
  File "/usr/local/lib/python3.7/site-packages/urllib3/util/retry.py", line 436, in increment
    raise MaxRetryError(_pool, url, error or ResponseError(cause))
urllib3.exceptions.MaxRetryError: HTTPSConnectionPool(host='cloud.yeradonkey.com', port=443): Max retries exceeded with url: /remote.php/dav/calendars/Squiggley/holidays/ (Caused by NewConnectionError('<urllib3.connection.VerifiedHTTPSConnection object at 0x7f5c89634c90>: Failed to establish a new connection: [Errno 111] Connection refused'))

During handling of the above exception, another exception occurred:

Traceback (most recent call last):
  File "/usr/src/homeassistant/homeassistant/helpers/entity.py", line 279, in async_update_ha_state
    await self.async_device_update()
  File "/usr/src/homeassistant/homeassistant/helpers/entity.py", line 461, in async_device_update
    await self.hass.async_add_executor_job(self.update)
  File "/usr/local/lib/python3.7/concurrent/futures/thread.py", line 57, in run
    result = self.fn(*self.args, **self.kwargs)
  File "/usr/src/homeassistant/homeassistant/components/caldav/calendar.py", line 145, in update
    self.data.update()
  File "/usr/src/homeassistant/homeassistant/util/__init__.py", line 240, in wrapper
    result = method(*args, **kwargs)
  File "/usr/src/homeassistant/homeassistant/components/caldav/calendar.py", line 199, in update
    dt.start_of_local_day(), dt.start_of_local_day() + timedelta(days=1)
  File "/usr/local/lib/python3.7/site-packages/caldav/objects.py", line 594, in date_search
    response = self._query(root, 1, 'report')
  File "/usr/local/lib/python3.7/site-packages/caldav/objects.py", line 161, in _query
    url, body, depth)
  File "/usr/local/lib/python3.7/site-packages/caldav/davclient.py", line 163, in report
    "application/xml; charset=\"utf-8\""})
  File "/usr/local/lib/python3.7/site-packages/caldav/davclient.py", line 237, in request
    auth=auth, verify=self.ssl_verify_cert)
  File "/usr/local/lib/python3.7/site-packages/requests/api.py", line 60, in request
    return session.request(method=method, url=url, **kwargs)
  File "/usr/local/lib/python3.7/site-packages/requests/sessions.py", line 533, in request
    resp = self.send(prep, **send_kwargs)
  File "/usr/local/lib/python3.7/site-packages/requests/sessions.py", line 646, in send
    r = adapter.send(request, **kwargs)
  File "/usr/local/lib/python3.7/site-packages/requests/adapters.py", line 516, in send
    raise ConnectionError(e, request=request)
requests.exceptions.ConnectionError: HTTPSConnectionPool(host='cloud.yeradonkey.com', port=443): Max retries exceeded with url: /remote.php/dav/calendars/Squiggley/holidays/ (Caused by NewConnectionError('<urllib3.connection.VerifiedHTTPSConnection object at 0x7f5c89634c90>: Failed to establish a new connection: [Errno 111] Connection refused'))
2020-02-24 13:08:47 ERROR (MainThread) [pytautulli] Can not load data from Tautulli: http://192.168.13.1:8181/api/v2?apikey=ae776b94fe9546989cf62d6fa5f732ab&cmd=get_activity - 
2020-02-24 13:09:49 ERROR (MainThread) [pytautulli] Can not load data from Tautulli: http://192.168.13.1:8181/api/v2?apikey=ae776b94fe9546989cf62d6fa5f732ab&cmd=get_activity - 
2020-02-24 13:43:34 ERROR (MainThread) [homeassistant.core] Error doing job: Unclosed connection
