2020-02-28 06:22:06 WARNING (MainThread) [homeassistant.loader] You are using a custom integration for smartir which has not been tested by Home Assistant. This component might cause stability problems, be sure to disable it if you do experience issues with Home Assistant.
2020-02-28 06:22:06 WARNING (MainThread) [homeassistant.loader] You are using a custom integration for zigbee2mqtt_networkmap which has not been tested by Home Assistant. This component might cause stability problems, be sure to disable it if you do experience issues with Home Assistant.
2020-02-28 06:22:06 WARNING (MainThread) [homeassistant.loader] You are using a custom integration for hacs which has not been tested by Home Assistant. This component might cause stability problems, be sure to disable it if you do experience issues with Home Assistant.
2020-02-28 06:23:47 ERROR (MainThread) [homeassistant.helpers.entity] Update for sensor.internet_out_mbps fails
Traceback (most recent call last):
  File "/usr/src/homeassistant/homeassistant/helpers/entity.py", line 279, in async_update_ha_state
    await self.async_device_update()
  File "/usr/src/homeassistant/homeassistant/helpers/entity.py", line 474, in async_device_update
    await self.async_update()
  File "/usr/src/homeassistant/homeassistant/components/template/sensor.py", line 224, in async_update
    self._state = self._template.async_render()
  File "/usr/src/homeassistant/homeassistant/helpers/template.py", line 221, in async_render
    return compiled.render(kwargs).strip()
  File "/usr/local/lib/python3.7/site-packages/jinja2/environment.py", line 1090, in render
    self.environment.handle_exception()
  File "/usr/local/lib/python3.7/site-packages/jinja2/environment.py", line 832, in handle_exception
    reraise(*rewrite_traceback_stack(source=source))
  File "/usr/local/lib/python3.7/site-packages/jinja2/_compat.py", line 28, in reraise
    raise value.with_traceback(tb)
  File "<template>", line 1, in top-level template code
TypeError: unsupported operand type(s) for -: 'NoneType' and 'int'
2020-02-28 06:23:47 ERROR (MainThread) [homeassistant.helpers.entity] Update for sensor.internet_in_mbps fails
Traceback (most recent call last):
  File "/usr/src/homeassistant/homeassistant/helpers/entity.py", line 279, in async_update_ha_state
    await self.async_device_update()
  File "/usr/src/homeassistant/homeassistant/helpers/entity.py", line 474, in async_device_update
    await self.async_update()
  File "/usr/src/homeassistant/homeassistant/components/template/sensor.py", line 224, in async_update
    self._state = self._template.async_render()
  File "/usr/src/homeassistant/homeassistant/helpers/template.py", line 221, in async_render
    return compiled.render(kwargs).strip()
  File "/usr/local/lib/python3.7/site-packages/jinja2/environment.py", line 1090, in render
    self.environment.handle_exception()
  File "/usr/local/lib/python3.7/site-packages/jinja2/environment.py", line 832, in handle_exception
    reraise(*rewrite_traceback_stack(source=source))
  File "/usr/local/lib/python3.7/site-packages/jinja2/_compat.py", line 28, in reraise
    raise value.with_traceback(tb)
  File "<template>", line 1, in top-level template code
TypeError: unsupported operand type(s) for -: 'NoneType' and 'int'
2020-02-28 07:00:18 ERROR (MainThread) [homeassistant.helpers.service] Error rendering data template: UndefinedError: 'None' has no attribute 'state'
2020-02-28 08:13:00 ERROR (MainThread) [homeassistant.components.script] Error executing script script.pulselight_stop. Invalid data for call_service at pos 1: Entity ID none is an invalid entity id for dictionary value @ data['entity_id']
2020-02-28 08:13:00 ERROR (MainThread) [homeassistant.components.automation] Error while executing automation automation.car_defroster_stop_monitoring_temperature. Invalid data for call_service at pos 2: Entity ID none is an invalid entity id for dictionary value @ data['entity_id']
2020-02-28 14:43:08 ERROR (MainThread) [homeassistant.components.homeassistant] homeassistant/turn_on cannot be called without entity_id
2020-02-28 14:43:08 ERROR (MainThread) [homeassistant.components.homeassistant] homeassistant/turn_on cannot be called without entity_id
2020-02-28 14:43:41 ERROR (MainThread) [homeassistant.components.homeassistant] homeassistant/turn_off cannot be called without entity_id
2020-02-28 14:43:41 ERROR (MainThread) [homeassistant.components.homeassistant] homeassistant/turn_off cannot be called without entity_id
2020-02-28 16:40:46 ERROR (MainThread) [homeassistant.helpers.service] Error rendering data template: UndefinedError: 'None' has no attribute 'state'
2020-02-28 16:40:47 ERROR (MainThread) [homeassistant.helpers.service] Error rendering data template: UndefinedError: 'None' has no attribute 'state'
2020-02-28 18:16:26 ERROR (MainThread) [homeassistant.helpers.entity] Update for sensor.plex_heart_of_gold fails
Traceback (most recent call last):
  File "/usr/local/lib/python3.7/site-packages/requests/models.py", line 379, in prepare_url
    scheme, auth, host, port, path, query, fragment = parse_url(url)
  File "/usr/local/lib/python3.7/site-packages/urllib3/util/url.py", line 392, in parse_url
    return six.raise_from(LocationParseError(source_url), None)
  File "<string>", line 3, in raise_from
urllib3.exceptions.LocationParseError: Failed to parse: https://77-102-146-10.dda3183be4074474b8fd75a81f3b1d20.plex.direct:32400None

During handling of the above exception, another exception occurred:

Traceback (most recent call last):
  File "/usr/src/homeassistant/homeassistant/helpers/entity.py", line 279, in async_update_ha_state
    await self.async_device_update()
  File "/usr/src/homeassistant/homeassistant/helpers/entity.py", line 476, in async_device_update
    await self.hass.async_add_executor_job(self.update)
  File "/usr/local/lib/python3.7/concurrent/futures/thread.py", line 57, in run
    result = self.fn(*self.args, **self.kwargs)
  File "/usr/src/homeassistant/homeassistant/components/plex/sensor.py", line 116, in update
    if sess.show().year is not None:
  File "/usr/local/lib/python3.7/site-packages/plexapi/video.py", line 625, in show
    return self.fetchItem(self.grandparentKey)
  File "/usr/local/lib/python3.7/site-packages/plexapi/base.py", line 137, in fetchItem
    for elem in self._server.query(ekey):
  File "/usr/local/lib/python3.7/site-packages/plexapi/server.py", line 376, in query
    response = method(url, headers=headers, timeout=timeout, **kwargs)
  File "/usr/local/lib/python3.7/site-packages/requests/sessions.py", line 546, in get
    return self.request('GET', url, **kwargs)
  File "/usr/local/lib/python3.7/site-packages/requests/sessions.py", line 519, in request
    prep = self.prepare_request(req)
  File "/usr/local/lib/python3.7/site-packages/requests/sessions.py", line 462, in prepare_request
    hooks=merge_hooks(request.hooks, self.hooks),
  File "/usr/local/lib/python3.7/site-packages/requests/models.py", line 313, in prepare
    self.prepare_url(url, params)
  File "/usr/local/lib/python3.7/site-packages/requests/models.py", line 381, in prepare_url
    raise InvalidURL(*e.args)
requests.exceptions.InvalidURL: Failed to parse: https://77-102-146-10.dda3183be4074474b8fd75a81f3b1d20.plex.direct:32400None
2020-02-28 18:45:21 ERROR (MainThread) [homeassistant.helpers.entity] Update for sensor.plex_heart_of_gold fails
Traceback (most recent call last):
  File "/usr/local/lib/python3.7/site-packages/requests/models.py", line 379, in prepare_url
    scheme, auth, host, port, path, query, fragment = parse_url(url)
  File "/usr/local/lib/python3.7/site-packages/urllib3/util/url.py", line 392, in parse_url
    return six.raise_from(LocationParseError(source_url), None)
  File "<string>", line 3, in raise_from
urllib3.exceptions.LocationParseError: Failed to parse: https://77-102-146-10.dda3183be4074474b8fd75a81f3b1d20.plex.direct:32400None

During handling of the above exception, another exception occurred:

Traceback (most recent call last):
  File "/usr/src/homeassistant/homeassistant/helpers/entity.py", line 279, in async_update_ha_state
    await self.async_device_update()
  File "/usr/src/homeassistant/homeassistant/helpers/entity.py", line 476, in async_device_update
    await self.hass.async_add_executor_job(self.update)
  File "/usr/local/lib/python3.7/concurrent/futures/thread.py", line 57, in run
    result = self.fn(*self.args, **self.kwargs)
  File "/usr/src/homeassistant/homeassistant/components/plex/sensor.py", line 116, in update
    if sess.show().year is not None:
  File "/usr/local/lib/python3.7/site-packages/plexapi/video.py", line 625, in show
    return self.fetchItem(self.grandparentKey)
  File "/usr/local/lib/python3.7/site-packages/plexapi/base.py", line 137, in fetchItem
    for elem in self._server.query(ekey):
  File "/usr/local/lib/python3.7/site-packages/plexapi/server.py", line 376, in query
    response = method(url, headers=headers, timeout=timeout, **kwargs)
  File "/usr/local/lib/python3.7/site-packages/requests/sessions.py", line 546, in get
    return self.request('GET', url, **kwargs)
  File "/usr/local/lib/python3.7/site-packages/requests/sessions.py", line 519, in request
    prep = self.prepare_request(req)
  File "/usr/local/lib/python3.7/site-packages/requests/sessions.py", line 462, in prepare_request
    hooks=merge_hooks(request.hooks, self.hooks),
  File "/usr/local/lib/python3.7/site-packages/requests/models.py", line 313, in prepare
    self.prepare_url(url, params)
  File "/usr/local/lib/python3.7/site-packages/requests/models.py", line 381, in prepare_url
    raise InvalidURL(*e.args)
requests.exceptions.InvalidURL: Failed to parse: https://77-102-146-10.dda3183be4074474b8fd75a81f3b1d20.plex.direct:32400None
2020-02-28 18:52:23 ERROR (MainThread) [homeassistant.helpers.service] Error rendering data template: UndefinedError: 'None' has no attribute 'state'
2020-02-28 18:58:58 ERROR (MainThread) [homeassistant.helpers.service] Error rendering data template: UndefinedError: 'None' has no attribute 'state'
2020-02-28 18:59:15 ERROR (MainThread) [homeassistant.helpers.service] Error rendering data template: UndefinedError: 'None' has no attribute 'state'
2020-02-28 19:08:44 ERROR (MainThread) [homeassistant.helpers.entity] Update for sensor.plex_heart_of_gold fails
Traceback (most recent call last):
  File "/usr/local/lib/python3.7/site-packages/requests/models.py", line 379, in prepare_url
    scheme, auth, host, port, path, query, fragment = parse_url(url)
  File "/usr/local/lib/python3.7/site-packages/urllib3/util/url.py", line 392, in parse_url
    return six.raise_from(LocationParseError(source_url), None)
  File "<string>", line 3, in raise_from
urllib3.exceptions.LocationParseError: Failed to parse: https://77-102-146-10.dda3183be4074474b8fd75a81f3b1d20.plex.direct:32400None

During handling of the above exception, another exception occurred:

Traceback (most recent call last):
  File "/usr/src/homeassistant/homeassistant/helpers/entity.py", line 279, in async_update_ha_state
    await self.async_device_update()
  File "/usr/src/homeassistant/homeassistant/helpers/entity.py", line 476, in async_device_update
    await self.hass.async_add_executor_job(self.update)
  File "/usr/local/lib/python3.7/concurrent/futures/thread.py", line 57, in run
    result = self.fn(*self.args, **self.kwargs)
  File "/usr/src/homeassistant/homeassistant/components/plex/sensor.py", line 116, in update
    if sess.show().year is not None:
  File "/usr/local/lib/python3.7/site-packages/plexapi/video.py", line 625, in show
    return self.fetchItem(self.grandparentKey)
  File "/usr/local/lib/python3.7/site-packages/plexapi/base.py", line 137, in fetchItem
    for elem in self._server.query(ekey):
  File "/usr/local/lib/python3.7/site-packages/plexapi/server.py", line 376, in query
    response = method(url, headers=headers, timeout=timeout, **kwargs)
  File "/usr/local/lib/python3.7/site-packages/requests/sessions.py", line 546, in get
    return self.request('GET', url, **kwargs)
  File "/usr/local/lib/python3.7/site-packages/requests/sessions.py", line 519, in request
    prep = self.prepare_request(req)
  File "/usr/local/lib/python3.7/site-packages/requests/sessions.py", line 462, in prepare_request
    hooks=merge_hooks(request.hooks, self.hooks),
  File "/usr/local/lib/python3.7/site-packages/requests/models.py", line 313, in prepare
    self.prepare_url(url, params)
  File "/usr/local/lib/python3.7/site-packages/requests/models.py", line 381, in prepare_url
    raise InvalidURL(*e.args)
requests.exceptions.InvalidURL: Failed to parse: https://77-102-146-10.dda3183be4074474b8fd75a81f3b1d20.plex.direct:32400None
2020-02-28 19:09:03 ERROR (MainThread) [homeassistant.helpers.entity] Update for sensor.plex_heart_of_gold fails
Traceback (most recent call last):
  File "/usr/local/lib/python3.7/site-packages/requests/models.py", line 379, in prepare_url
    scheme, auth, host, port, path, query, fragment = parse_url(url)
  File "/usr/local/lib/python3.7/site-packages/urllib3/util/url.py", line 392, in parse_url
    return six.raise_from(LocationParseError(source_url), None)
  File "<string>", line 3, in raise_from
urllib3.exceptions.LocationParseError: Failed to parse: https://77-102-146-10.dda3183be4074474b8fd75a81f3b1d20.plex.direct:32400None

During handling of the above exception, another exception occurred:

Traceback (most recent call last):
  File "/usr/src/homeassistant/homeassistant/helpers/entity.py", line 279, in async_update_ha_state
    await self.async_device_update()
  File "/usr/src/homeassistant/homeassistant/helpers/entity.py", line 476, in async_device_update
    await self.hass.async_add_executor_job(self.update)
  File "/usr/local/lib/python3.7/concurrent/futures/thread.py", line 57, in run
    result = self.fn(*self.args, **self.kwargs)
  File "/usr/src/homeassistant/homeassistant/components/plex/sensor.py", line 116, in update
    if sess.show().year is not None:
  File "/usr/local/lib/python3.7/site-packages/plexapi/video.py", line 625, in show
    return self.fetchItem(self.grandparentKey)
  File "/usr/local/lib/python3.7/site-packages/plexapi/base.py", line 137, in fetchItem
    for elem in self._server.query(ekey):
  File "/usr/local/lib/python3.7/site-packages/plexapi/server.py", line 376, in query
    response = method(url, headers=headers, timeout=timeout, **kwargs)
  File "/usr/local/lib/python3.7/site-packages/requests/sessions.py", line 546, in get
    return self.request('GET', url, **kwargs)
  File "/usr/local/lib/python3.7/site-packages/requests/sessions.py", line 519, in request
    prep = self.prepare_request(req)
  File "/usr/local/lib/python3.7/site-packages/requests/sessions.py", line 462, in prepare_request
    hooks=merge_hooks(request.hooks, self.hooks),
  File "/usr/local/lib/python3.7/site-packages/requests/models.py", line 313, in prepare
    self.prepare_url(url, params)
  File "/usr/local/lib/python3.7/site-packages/requests/models.py", line 381, in prepare_url
    raise InvalidURL(*e.args)
requests.exceptions.InvalidURL: Failed to parse: https://77-102-146-10.dda3183be4074474b8fd75a81f3b1d20.plex.direct:32400None
2020-02-28 19:38:36 ERROR (MainThread) [homeassistant.helpers.entity] Update for sensor.plex_heart_of_gold fails
Traceback (most recent call last):
  File "/usr/local/lib/python3.7/site-packages/requests/models.py", line 379, in prepare_url
    scheme, auth, host, port, path, query, fragment = parse_url(url)
  File "/usr/local/lib/python3.7/site-packages/urllib3/util/url.py", line 392, in parse_url
    return six.raise_from(LocationParseError(source_url), None)
  File "<string>", line 3, in raise_from
urllib3.exceptions.LocationParseError: Failed to parse: https://77-102-146-10.dda3183be4074474b8fd75a81f3b1d20.plex.direct:32400None

During handling of the above exception, another exception occurred:

Traceback (most recent call last):
  File "/usr/src/homeassistant/homeassistant/helpers/entity.py", line 279, in async_update_ha_state
    await self.async_device_update()
  File "/usr/src/homeassistant/homeassistant/helpers/entity.py", line 476, in async_device_update
    await self.hass.async_add_executor_job(self.update)
  File "/usr/local/lib/python3.7/concurrent/futures/thread.py", line 57, in run
    result = self.fn(*self.args, **self.kwargs)
  File "/usr/src/homeassistant/homeassistant/components/plex/sensor.py", line 116, in update
    if sess.show().year is not None:
  File "/usr/local/lib/python3.7/site-packages/plexapi/video.py", line 625, in show
    return self.fetchItem(self.grandparentKey)
  File "/usr/local/lib/python3.7/site-packages/plexapi/base.py", line 137, in fetchItem
    for elem in self._server.query(ekey):
  File "/usr/local/lib/python3.7/site-packages/plexapi/server.py", line 376, in query
    response = method(url, headers=headers, timeout=timeout, **kwargs)
  File "/usr/local/lib/python3.7/site-packages/requests/sessions.py", line 546, in get
    return self.request('GET', url, **kwargs)
  File "/usr/local/lib/python3.7/site-packages/requests/sessions.py", line 519, in request
    prep = self.prepare_request(req)
  File "/usr/local/lib/python3.7/site-packages/requests/sessions.py", line 462, in prepare_request
    hooks=merge_hooks(request.hooks, self.hooks),
  File "/usr/local/lib/python3.7/site-packages/requests/models.py", line 313, in prepare
    self.prepare_url(url, params)
  File "/usr/local/lib/python3.7/site-packages/requests/models.py", line 381, in prepare_url
    raise InvalidURL(*e.args)
requests.exceptions.InvalidURL: Failed to parse: https://77-102-146-10.dda3183be4074474b8fd75a81f3b1d20.plex.direct:32400None
2020-02-28 19:44:40 ERROR (MainThread) [homeassistant.helpers.service] Error rendering data template: UndefinedError: 'None' has no attribute 'state'
2020-02-28 19:44:41 ERROR (MainThread) [homeassistant.helpers.service] Error rendering data template: UndefinedError: 'None' has no attribute 'state'
2020-02-28 20:07:50 ERROR (MainThread) [homeassistant.helpers.entity] Update for sensor.plex_heart_of_gold fails
Traceback (most recent call last):
  File "/usr/local/lib/python3.7/site-packages/requests/models.py", line 379, in prepare_url
    scheme, auth, host, port, path, query, fragment = parse_url(url)
  File "/usr/local/lib/python3.7/site-packages/urllib3/util/url.py", line 392, in parse_url
    return six.raise_from(LocationParseError(source_url), None)
  File "<string>", line 3, in raise_from
urllib3.exceptions.LocationParseError: Failed to parse: https://77-102-146-10.dda3183be4074474b8fd75a81f3b1d20.plex.direct:32400None

During handling of the above exception, another exception occurred:

Traceback (most recent call last):
  File "/usr/src/homeassistant/homeassistant/helpers/entity.py", line 279, in async_update_ha_state
    await self.async_device_update()
  File "/usr/src/homeassistant/homeassistant/helpers/entity.py", line 476, in async_device_update
    await self.hass.async_add_executor_job(self.update)
  File "/usr/local/lib/python3.7/concurrent/futures/thread.py", line 57, in run
    result = self.fn(*self.args, **self.kwargs)
  File "/usr/src/homeassistant/homeassistant/components/plex/sensor.py", line 116, in update
    if sess.show().year is not None:
  File "/usr/local/lib/python3.7/site-packages/plexapi/video.py", line 625, in show
    return self.fetchItem(self.grandparentKey)
  File "/usr/local/lib/python3.7/site-packages/plexapi/base.py", line 137, in fetchItem
    for elem in self._server.query(ekey):
  File "/usr/local/lib/python3.7/site-packages/plexapi/server.py", line 376, in query
    response = method(url, headers=headers, timeout=timeout, **kwargs)
  File "/usr/local/lib/python3.7/site-packages/requests/sessions.py", line 546, in get
    return self.request('GET', url, **kwargs)
  File "/usr/local/lib/python3.7/site-packages/requests/sessions.py", line 519, in request
    prep = self.prepare_request(req)
  File "/usr/local/lib/python3.7/site-packages/requests/sessions.py", line 462, in prepare_request
    hooks=merge_hooks(request.hooks, self.hooks),
  File "/usr/local/lib/python3.7/site-packages/requests/models.py", line 313, in prepare
    self.prepare_url(url, params)
  File "/usr/local/lib/python3.7/site-packages/requests/models.py", line 381, in prepare_url
    raise InvalidURL(*e.args)
requests.exceptions.InvalidURL: Failed to parse: https://77-102-146-10.dda3183be4074474b8fd75a81f3b1d20.plex.direct:32400None
2020-02-28 20:42:49 ERROR (MainThread) [homeassistant.helpers.entity] Update for sensor.plex_heart_of_gold fails
Traceback (most recent call last):
  File "/usr/local/lib/python3.7/site-packages/requests/models.py", line 379, in prepare_url
    scheme, auth, host, port, path, query, fragment = parse_url(url)
  File "/usr/local/lib/python3.7/site-packages/urllib3/util/url.py", line 392, in parse_url
    return six.raise_from(LocationParseError(source_url), None)
  File "<string>", line 3, in raise_from
urllib3.exceptions.LocationParseError: Failed to parse: https://77-102-146-10.dda3183be4074474b8fd75a81f3b1d20.plex.direct:32400None

During handling of the above exception, another exception occurred:

Traceback (most recent call last):
  File "/usr/src/homeassistant/homeassistant/helpers/entity.py", line 279, in async_update_ha_state
    await self.async_device_update()
  File "/usr/src/homeassistant/homeassistant/helpers/entity.py", line 476, in async_device_update
    await self.hass.async_add_executor_job(self.update)
  File "/usr/local/lib/python3.7/concurrent/futures/thread.py", line 57, in run
    result = self.fn(*self.args, **self.kwargs)
  File "/usr/src/homeassistant/homeassistant/components/plex/sensor.py", line 116, in update
    if sess.show().year is not None:
  File "/usr/local/lib/python3.7/site-packages/plexapi/video.py", line 625, in show
    return self.fetchItem(self.grandparentKey)
  File "/usr/local/lib/python3.7/site-packages/plexapi/base.py", line 137, in fetchItem
    for elem in self._server.query(ekey):
  File "/usr/local/lib/python3.7/site-packages/plexapi/server.py", line 376, in query
    response = method(url, headers=headers, timeout=timeout, **kwargs)
  File "/usr/local/lib/python3.7/site-packages/requests/sessions.py", line 546, in get
    return self.request('GET', url, **kwargs)
  File "/usr/local/lib/python3.7/site-packages/requests/sessions.py", line 519, in request
    prep = self.prepare_request(req)
  File "/usr/local/lib/python3.7/site-packages/requests/sessions.py", line 462, in prepare_request
    hooks=merge_hooks(request.hooks, self.hooks),
  File "/usr/local/lib/python3.7/site-packages/requests/models.py", line 313, in prepare
    self.prepare_url(url, params)
  File "/usr/local/lib/python3.7/site-packages/requests/models.py", line 381, in prepare_url
    raise InvalidURL(*e.args)
requests.exceptions.InvalidURL: Failed to parse: https://77-102-146-10.dda3183be4074474b8fd75a81f3b1d20.plex.direct:32400None
2020-02-28 20:43:28 ERROR (MainThread) [homeassistant.helpers.entity] Update for sensor.plex_heart_of_gold fails
Traceback (most recent call last):
  File "/usr/local/lib/python3.7/site-packages/requests/models.py", line 379, in prepare_url
    scheme, auth, host, port, path, query, fragment = parse_url(url)
  File "/usr/local/lib/python3.7/site-packages/urllib3/util/url.py", line 392, in parse_url
    return six.raise_from(LocationParseError(source_url), None)
  File "<string>", line 3, in raise_from
urllib3.exceptions.LocationParseError: Failed to parse: https://77-102-146-10.dda3183be4074474b8fd75a81f3b1d20.plex.direct:32400None

During handling of the above exception, another exception occurred:

Traceback (most recent call last):
  File "/usr/src/homeassistant/homeassistant/helpers/entity.py", line 279, in async_update_ha_state
    await self.async_device_update()
  File "/usr/src/homeassistant/homeassistant/helpers/entity.py", line 476, in async_device_update
    await self.hass.async_add_executor_job(self.update)
  File "/usr/local/lib/python3.7/concurrent/futures/thread.py", line 57, in run
    result = self.fn(*self.args, **self.kwargs)
  File "/usr/src/homeassistant/homeassistant/components/plex/sensor.py", line 116, in update
    if sess.show().year is not None:
  File "/usr/local/lib/python3.7/site-packages/plexapi/video.py", line 625, in show
    return self.fetchItem(self.grandparentKey)
  File "/usr/local/lib/python3.7/site-packages/plexapi/base.py", line 137, in fetchItem
    for elem in self._server.query(ekey):
  File "/usr/local/lib/python3.7/site-packages/plexapi/server.py", line 376, in query
    response = method(url, headers=headers, timeout=timeout, **kwargs)
  File "/usr/local/lib/python3.7/site-packages/requests/sessions.py", line 546, in get
    return self.request('GET', url, **kwargs)
  File "/usr/local/lib/python3.7/site-packages/requests/sessions.py", line 519, in request
    prep = self.prepare_request(req)
  File "/usr/local/lib/python3.7/site-packages/requests/sessions.py", line 462, in prepare_request
    hooks=merge_hooks(request.hooks, self.hooks),
  File "/usr/local/lib/python3.7/site-packages/requests/models.py", line 313, in prepare
    self.prepare_url(url, params)
  File "/usr/local/lib/python3.7/site-packages/requests/models.py", line 381, in prepare_url
    raise InvalidURL(*e.args)
requests.exceptions.InvalidURL: Failed to parse: https://77-102-146-10.dda3183be4074474b8fd75a81f3b1d20.plex.direct:32400None
2020-02-28 20:43:30 ERROR (MainThread) [homeassistant.helpers.entity] Update for sensor.plex_heart_of_gold fails
Traceback (most recent call last):
  File "/usr/local/lib/python3.7/site-packages/requests/models.py", line 379, in prepare_url
    scheme, auth, host, port, path, query, fragment = parse_url(url)
  File "/usr/local/lib/python3.7/site-packages/urllib3/util/url.py", line 392, in parse_url
    return six.raise_from(LocationParseError(source_url), None)
  File "<string>", line 3, in raise_from
urllib3.exceptions.LocationParseError: Failed to parse: https://77-102-146-10.dda3183be4074474b8fd75a81f3b1d20.plex.direct:32400None

During handling of the above exception, another exception occurred:

Traceback (most recent call last):
  File "/usr/src/homeassistant/homeassistant/helpers/entity.py", line 279, in async_update_ha_state
    await self.async_device_update()
  File "/usr/src/homeassistant/homeassistant/helpers/entity.py", line 476, in async_device_update
    await self.hass.async_add_executor_job(self.update)
  File "/usr/local/lib/python3.7/concurrent/futures/thread.py", line 57, in run
    result = self.fn(*self.args, **self.kwargs)
  File "/usr/src/homeassistant/homeassistant/components/plex/sensor.py", line 116, in update
    if sess.show().year is not None:
  File "/usr/local/lib/python3.7/site-packages/plexapi/video.py", line 625, in show
    return self.fetchItem(self.grandparentKey)
  File "/usr/local/lib/python3.7/site-packages/plexapi/base.py", line 137, in fetchItem
    for elem in self._server.query(ekey):
  File "/usr/local/lib/python3.7/site-packages/plexapi/server.py", line 376, in query
    response = method(url, headers=headers, timeout=timeout, **kwargs)
  File "/usr/local/lib/python3.7/site-packages/requests/sessions.py", line 546, in get
    return self.request('GET', url, **kwargs)
  File "/usr/local/lib/python3.7/site-packages/requests/sessions.py", line 519, in request
    prep = self.prepare_request(req)
  File "/usr/local/lib/python3.7/site-packages/requests/sessions.py", line 462, in prepare_request
    hooks=merge_hooks(request.hooks, self.hooks),
  File "/usr/local/lib/python3.7/site-packages/requests/models.py", line 313, in prepare
    self.prepare_url(url, params)
  File "/usr/local/lib/python3.7/site-packages/requests/models.py", line 381, in prepare_url
    raise InvalidURL(*e.args)
requests.exceptions.InvalidURL: Failed to parse: https://77-102-146-10.dda3183be4074474b8fd75a81f3b1d20.plex.direct:32400None
2020-02-28 21:00:40 ERROR (MainThread) [homeassistant.core] Error doing job: Task exception was never retrieved
RuntimeError: cannot reuse already awaited coroutine
2020-02-28 21:12:34 ERROR (MainThread) [homeassistant.helpers.entity] Update for sensor.plex_heart_of_gold fails
Traceback (most recent call last):
  File "/usr/local/lib/python3.7/site-packages/requests/models.py", line 379, in prepare_url
    scheme, auth, host, port, path, query, fragment = parse_url(url)
  File "/usr/local/lib/python3.7/site-packages/urllib3/util/url.py", line 392, in parse_url
    return six.raise_from(LocationParseError(source_url), None)
  File "<string>", line 3, in raise_from
urllib3.exceptions.LocationParseError: Failed to parse: https://77-102-146-10.dda3183be4074474b8fd75a81f3b1d20.plex.direct:32400None

During handling of the above exception, another exception occurred:

Traceback (most recent call last):
  File "/usr/src/homeassistant/homeassistant/helpers/entity.py", line 279, in async_update_ha_state
    await self.async_device_update()
  File "/usr/src/homeassistant/homeassistant/helpers/entity.py", line 476, in async_device_update
    await self.hass.async_add_executor_job(self.update)
  File "/usr/local/lib/python3.7/concurrent/futures/thread.py", line 57, in run
    result = self.fn(*self.args, **self.kwargs)
  File "/usr/src/homeassistant/homeassistant/components/plex/sensor.py", line 116, in update
    if sess.show().year is not None:
  File "/usr/local/lib/python3.7/site-packages/plexapi/video.py", line 625, in show
    return self.fetchItem(self.grandparentKey)
  File "/usr/local/lib/python3.7/site-packages/plexapi/base.py", line 137, in fetchItem
    for elem in self._server.query(ekey):
  File "/usr/local/lib/python3.7/site-packages/plexapi/server.py", line 376, in query
    response = method(url, headers=headers, timeout=timeout, **kwargs)
  File "/usr/local/lib/python3.7/site-packages/requests/sessions.py", line 546, in get
    return self.request('GET', url, **kwargs)
  File "/usr/local/lib/python3.7/site-packages/requests/sessions.py", line 519, in request
    prep = self.prepare_request(req)
  File "/usr/local/lib/python3.7/site-packages/requests/sessions.py", line 462, in prepare_request
    hooks=merge_hooks(request.hooks, self.hooks),
  File "/usr/local/lib/python3.7/site-packages/requests/models.py", line 313, in prepare
    self.prepare_url(url, params)
  File "/usr/local/lib/python3.7/site-packages/requests/models.py", line 381, in prepare_url
    raise InvalidURL(*e.args)
requests.exceptions.InvalidURL: Failed to parse: https://77-102-146-10.dda3183be4074474b8fd75a81f3b1d20.plex.direct:32400None
2020-02-28 21:35:20 ERROR (MainThread) [homeassistant.helpers.entity] Update for sensor.plex_heart_of_gold fails
Traceback (most recent call last):
  File "/usr/local/lib/python3.7/site-packages/requests/models.py", line 379, in prepare_url
    scheme, auth, host, port, path, query, fragment = parse_url(url)
  File "/usr/local/lib/python3.7/site-packages/urllib3/util/url.py", line 392, in parse_url
    return six.raise_from(LocationParseError(source_url), None)
  File "<string>", line 3, in raise_from
urllib3.exceptions.LocationParseError: Failed to parse: https://77-102-146-10.dda3183be4074474b8fd75a81f3b1d20.plex.direct:32400None

During handling of the above exception, another exception occurred:

Traceback (most recent call last):
  File "/usr/src/homeassistant/homeassistant/helpers/entity.py", line 279, in async_update_ha_state
    await self.async_device_update()
  File "/usr/src/homeassistant/homeassistant/helpers/entity.py", line 476, in async_device_update
    await self.hass.async_add_executor_job(self.update)
  File "/usr/local/lib/python3.7/concurrent/futures/thread.py", line 57, in run
    result = self.fn(*self.args, **self.kwargs)
  File "/usr/src/homeassistant/homeassistant/components/plex/sensor.py", line 116, in update
    if sess.show().year is not None:
  File "/usr/local/lib/python3.7/site-packages/plexapi/video.py", line 625, in show
    return self.fetchItem(self.grandparentKey)
  File "/usr/local/lib/python3.7/site-packages/plexapi/base.py", line 137, in fetchItem
    for elem in self._server.query(ekey):
  File "/usr/local/lib/python3.7/site-packages/plexapi/server.py", line 376, in query
    response = method(url, headers=headers, timeout=timeout, **kwargs)
  File "/usr/local/lib/python3.7/site-packages/requests/sessions.py", line 546, in get
    return self.request('GET', url, **kwargs)
  File "/usr/local/lib/python3.7/site-packages/requests/sessions.py", line 519, in request
    prep = self.prepare_request(req)
  File "/usr/local/lib/python3.7/site-packages/requests/sessions.py", line 462, in prepare_request
    hooks=merge_hooks(request.hooks, self.hooks),
  File "/usr/local/lib/python3.7/site-packages/requests/models.py", line 313, in prepare
    self.prepare_url(url, params)
  File "/usr/local/lib/python3.7/site-packages/requests/models.py", line 381, in prepare_url
    raise InvalidURL(*e.args)
requests.exceptions.InvalidURL: Failed to parse: https://77-102-146-10.dda3183be4074474b8fd75a81f3b1d20.plex.direct:32400None
2020-02-28 21:42:03 ERROR (MainThread) [homeassistant.helpers.service] Error rendering data template: UndefinedError: 'None' has no attribute 'state'
2020-02-28 21:42:03 ERROR (MainThread) [homeassistant.helpers.service] Error rendering data template: UndefinedError: 'None' has no attribute 'state'
2020-02-28 21:42:33 ERROR (MainThread) [homeassistant.helpers.entity] Update for sensor.plex_heart_of_gold fails
Traceback (most recent call last):
  File "/usr/local/lib/python3.7/site-packages/requests/models.py", line 379, in prepare_url
    scheme, auth, host, port, path, query, fragment = parse_url(url)
  File "/usr/local/lib/python3.7/site-packages/urllib3/util/url.py", line 392, in parse_url
    return six.raise_from(LocationParseError(source_url), None)
  File "<string>", line 3, in raise_from
urllib3.exceptions.LocationParseError: Failed to parse: https://77-102-146-10.dda3183be4074474b8fd75a81f3b1d20.plex.direct:32400None

During handling of the above exception, another exception occurred:

Traceback (most recent call last):
  File "/usr/src/homeassistant/homeassistant/helpers/entity.py", line 279, in async_update_ha_state
    await self.async_device_update()
  File "/usr/src/homeassistant/homeassistant/helpers/entity.py", line 476, in async_device_update
    await self.hass.async_add_executor_job(self.update)
  File "/usr/local/lib/python3.7/concurrent/futures/thread.py", line 57, in run
    result = self.fn(*self.args, **self.kwargs)
  File "/usr/src/homeassistant/homeassistant/components/plex/sensor.py", line 116, in update
    if sess.show().year is not None:
  File "/usr/local/lib/python3.7/site-packages/plexapi/video.py", line 625, in show
    return self.fetchItem(self.grandparentKey)
  File "/usr/local/lib/python3.7/site-packages/plexapi/base.py", line 137, in fetchItem
    for elem in self._server.query(ekey):
  File "/usr/local/lib/python3.7/site-packages/plexapi/server.py", line 376, in query
    response = method(url, headers=headers, timeout=timeout, **kwargs)
  File "/usr/local/lib/python3.7/site-packages/requests/sessions.py", line 546, in get
    return self.request('GET', url, **kwargs)
  File "/usr/local/lib/python3.7/site-packages/requests/sessions.py", line 519, in request
    prep = self.prepare_request(req)
  File "/usr/local/lib/python3.7/site-packages/requests/sessions.py", line 462, in prepare_request
    hooks=merge_hooks(request.hooks, self.hooks),
  File "/usr/local/lib/python3.7/site-packages/requests/models.py", line 313, in prepare
    self.prepare_url(url, params)
  File "/usr/local/lib/python3.7/site-packages/requests/models.py", line 381, in prepare_url
    raise InvalidURL(*e.args)
requests.exceptions.InvalidURL: Failed to parse: https://77-102-146-10.dda3183be4074474b8fd75a81f3b1d20.plex.direct:32400None
2020-02-28 21:42:42 ERROR (MainThread) [homeassistant.helpers.entity] Update for sensor.plex_heart_of_gold fails
Traceback (most recent call last):
  File "/usr/local/lib/python3.7/site-packages/requests/models.py", line 379, in prepare_url
    scheme, auth, host, port, path, query, fragment = parse_url(url)
  File "/usr/local/lib/python3.7/site-packages/urllib3/util/url.py", line 392, in parse_url
    return six.raise_from(LocationParseError(source_url), None)
  File "<string>", line 3, in raise_from
urllib3.exceptions.LocationParseError: Failed to parse: https://77-102-146-10.dda3183be4074474b8fd75a81f3b1d20.plex.direct:32400None

During handling of the above exception, another exception occurred:

Traceback (most recent call last):
  File "/usr/src/homeassistant/homeassistant/helpers/entity.py", line 279, in async_update_ha_state
    await self.async_device_update()
  File "/usr/src/homeassistant/homeassistant/helpers/entity.py", line 476, in async_device_update
    await self.hass.async_add_executor_job(self.update)
  File "/usr/local/lib/python3.7/concurrent/futures/thread.py", line 57, in run
    result = self.fn(*self.args, **self.kwargs)
  File "/usr/src/homeassistant/homeassistant/components/plex/sensor.py", line 116, in update
    if sess.show().year is not None:
  File "/usr/local/lib/python3.7/site-packages/plexapi/video.py", line 625, in show
    return self.fetchItem(self.grandparentKey)
  File "/usr/local/lib/python3.7/site-packages/plexapi/base.py", line 137, in fetchItem
    for elem in self._server.query(ekey):
  File "/usr/local/lib/python3.7/site-packages/plexapi/server.py", line 376, in query
    response = method(url, headers=headers, timeout=timeout, **kwargs)
  File "/usr/local/lib/python3.7/site-packages/requests/sessions.py", line 546, in get
    return self.request('GET', url, **kwargs)
  File "/usr/local/lib/python3.7/site-packages/requests/sessions.py", line 519, in request
    prep = self.prepare_request(req)
  File "/usr/local/lib/python3.7/site-packages/requests/sessions.py", line 462, in prepare_request
    hooks=merge_hooks(request.hooks, self.hooks),
  File "/usr/local/lib/python3.7/site-packages/requests/models.py", line 313, in prepare
    self.prepare_url(url, params)
  File "/usr/local/lib/python3.7/site-packages/requests/models.py", line 381, in prepare_url
    raise InvalidURL(*e.args)
requests.exceptions.InvalidURL: Failed to parse: https://77-102-146-10.dda3183be4074474b8fd75a81f3b1d20.plex.direct:32400None
2020-02-28 21:43:44 ERROR (MainThread) [homeassistant.helpers.entity] Update for sensor.plex_heart_of_gold fails
Traceback (most recent call last):
  File "/usr/local/lib/python3.7/site-packages/requests/models.py", line 379, in prepare_url
    scheme, auth, host, port, path, query, fragment = parse_url(url)
  File "/usr/local/lib/python3.7/site-packages/urllib3/util/url.py", line 392, in parse_url
    return six.raise_from(LocationParseError(source_url), None)
  File "<string>", line 3, in raise_from
urllib3.exceptions.LocationParseError: Failed to parse: https://77-102-146-10.dda3183be4074474b8fd75a81f3b1d20.plex.direct:32400None

During handling of the above exception, another exception occurred:

Traceback (most recent call last):
  File "/usr/src/homeassistant/homeassistant/helpers/entity.py", line 279, in async_update_ha_state
    await self.async_device_update()
  File "/usr/src/homeassistant/homeassistant/helpers/entity.py", line 476, in async_device_update
    await self.hass.async_add_executor_job(self.update)
  File "/usr/local/lib/python3.7/concurrent/futures/thread.py", line 57, in run
    result = self.fn(*self.args, **self.kwargs)
  File "/usr/src/homeassistant/homeassistant/components/plex/sensor.py", line 116, in update
    if sess.show().year is not None:
  File "/usr/local/lib/python3.7/site-packages/plexapi/video.py", line 625, in show
    return self.fetchItem(self.grandparentKey)
  File "/usr/local/lib/python3.7/site-packages/plexapi/base.py", line 137, in fetchItem
    for elem in self._server.query(ekey):
  File "/usr/local/lib/python3.7/site-packages/plexapi/server.py", line 376, in query
    response = method(url, headers=headers, timeout=timeout, **kwargs)
  File "/usr/local/lib/python3.7/site-packages/requests/sessions.py", line 546, in get
    return self.request('GET', url, **kwargs)
  File "/usr/local/lib/python3.7/site-packages/requests/sessions.py", line 519, in request
    prep = self.prepare_request(req)
  File "/usr/local/lib/python3.7/site-packages/requests/sessions.py", line 462, in prepare_request
    hooks=merge_hooks(request.hooks, self.hooks),
  File "/usr/local/lib/python3.7/site-packages/requests/models.py", line 313, in prepare
    self.prepare_url(url, params)
  File "/usr/local/lib/python3.7/site-packages/requests/models.py", line 381, in prepare_url
    raise InvalidURL(*e.args)
requests.exceptions.InvalidURL: Failed to parse: https://77-102-146-10.dda3183be4074474b8fd75a81f3b1d20.plex.direct:32400None
2020-02-28 21:44:04 ERROR (MainThread) [homeassistant.helpers.entity] Update for sensor.plex_heart_of_gold fails
Traceback (most recent call last):
  File "/usr/local/lib/python3.7/site-packages/requests/models.py", line 379, in prepare_url
    scheme, auth, host, port, path, query, fragment = parse_url(url)
  File "/usr/local/lib/python3.7/site-packages/urllib3/util/url.py", line 392, in parse_url
    return six.raise_from(LocationParseError(source_url), None)
  File "<string>", line 3, in raise_from
urllib3.exceptions.LocationParseError: Failed to parse: https://77-102-146-10.dda3183be4074474b8fd75a81f3b1d20.plex.direct:32400None

During handling of the above exception, another exception occurred:

Traceback (most recent call last):
  File "/usr/src/homeassistant/homeassistant/helpers/entity.py", line 279, in async_update_ha_state
    await self.async_device_update()
  File "/usr/src/homeassistant/homeassistant/helpers/entity.py", line 476, in async_device_update
    await self.hass.async_add_executor_job(self.update)
  File "/usr/local/lib/python3.7/concurrent/futures/thread.py", line 57, in run
    result = self.fn(*self.args, **self.kwargs)
  File "/usr/src/homeassistant/homeassistant/components/plex/sensor.py", line 116, in update
    if sess.show().year is not None:
  File "/usr/local/lib/python3.7/site-packages/plexapi/video.py", line 625, in show
    return self.fetchItem(self.grandparentKey)
  File "/usr/local/lib/python3.7/site-packages/plexapi/base.py", line 137, in fetchItem
    for elem in self._server.query(ekey):
  File "/usr/local/lib/python3.7/site-packages/plexapi/server.py", line 376, in query
    response = method(url, headers=headers, timeout=timeout, **kwargs)
  File "/usr/local/lib/python3.7/site-packages/requests/sessions.py", line 546, in get
    return self.request('GET', url, **kwargs)
  File "/usr/local/lib/python3.7/site-packages/requests/sessions.py", line 519, in request
    prep = self.prepare_request(req)
  File "/usr/local/lib/python3.7/site-packages/requests/sessions.py", line 462, in prepare_request
    hooks=merge_hooks(request.hooks, self.hooks),
  File "/usr/local/lib/python3.7/site-packages/requests/models.py", line 313, in prepare
    self.prepare_url(url, params)
  File "/usr/local/lib/python3.7/site-packages/requests/models.py", line 381, in prepare_url
    raise InvalidURL(*e.args)
requests.exceptions.InvalidURL: Failed to parse: https://77-102-146-10.dda3183be4074474b8fd75a81f3b1d20.plex.direct:32400None
2020-02-28 21:45:51 ERROR (MainThread) [homeassistant.helpers.entity] Update for sensor.plex_heart_of_gold fails
Traceback (most recent call last):
  File "/usr/local/lib/python3.7/site-packages/requests/models.py", line 379, in prepare_url
    scheme, auth, host, port, path, query, fragment = parse_url(url)
  File "/usr/local/lib/python3.7/site-packages/urllib3/util/url.py", line 392, in parse_url
    return six.raise_from(LocationParseError(source_url), None)
  File "<string>", line 3, in raise_from
urllib3.exceptions.LocationParseError: Failed to parse: https://77-102-146-10.dda3183be4074474b8fd75a81f3b1d20.plex.direct:32400None

During handling of the above exception, another exception occurred:

Traceback (most recent call last):
  File "/usr/src/homeassistant/homeassistant/helpers/entity.py", line 279, in async_update_ha_state
    await self.async_device_update()
  File "/usr/src/homeassistant/homeassistant/helpers/entity.py", line 476, in async_device_update
    await self.hass.async_add_executor_job(self.update)
  File "/usr/local/lib/python3.7/concurrent/futures/thread.py", line 57, in run
    result = self.fn(*self.args, **self.kwargs)
  File "/usr/src/homeassistant/homeassistant/components/plex/sensor.py", line 116, in update
    if sess.show().year is not None:
  File "/usr/local/lib/python3.7/site-packages/plexapi/video.py", line 625, in show
    return self.fetchItem(self.grandparentKey)
  File "/usr/local/lib/python3.7/site-packages/plexapi/base.py", line 137, in fetchItem
    for elem in self._server.query(ekey):
  File "/usr/local/lib/python3.7/site-packages/plexapi/server.py", line 376, in query
    response = method(url, headers=headers, timeout=timeout, **kwargs)
  File "/usr/local/lib/python3.7/site-packages/requests/sessions.py", line 546, in get
    return self.request('GET', url, **kwargs)
  File "/usr/local/lib/python3.7/site-packages/requests/sessions.py", line 519, in request
    prep = self.prepare_request(req)
  File "/usr/local/lib/python3.7/site-packages/requests/sessions.py", line 462, in prepare_request
    hooks=merge_hooks(request.hooks, self.hooks),
  File "/usr/local/lib/python3.7/site-packages/requests/models.py", line 313, in prepare
    self.prepare_url(url, params)
  File "/usr/local/lib/python3.7/site-packages/requests/models.py", line 381, in prepare_url
    raise InvalidURL(*e.args)
requests.exceptions.InvalidURL: Failed to parse: https://77-102-146-10.dda3183be4074474b8fd75a81f3b1d20.plex.direct:32400None
2020-02-28 22:35:30 ERROR (MainThread) [homeassistant.helpers.service] Error rendering data template: UndefinedError: 'None' has no attribute 'state'
